INFO       - 2023-09-18 00:55:31,155 - client          : logging in using static token
INFO       - 2023-09-18 00:55:54,836 - gateway         : Shard ID None has connected to Gateway (Session ID: 1afc903f96a61f1da41fa55817731df8).
ERROR      - 2023-09-18 00:56:26,283 - bot             : Ignoring exception in command mapdata
Traceback (most recent call last):
  File "E:\Onepiecebot\Discordop\lib\site-packages\discord\ext\commands\core.py", line 235, in wrapped
    ret = await coro(*args, **kwargs)
  File "e:\Onepiecebot\Cmds\Start.py", line 19, in mapdata
    island(server_id=ctx.guild.id)
  File "e:\Onepiecebot\extra_function.py", line 79, in add_parts_to_island
    parts_list.append(add_part("port", port_dim, island_data))
  File "e:\Onepiecebot\extra_function.py", line 51, in add_part
    result = check_fit(part_dim, island_data)
  File "e:\Onepiecebot\extra_function.py", line 25, in check_fit
    boundary_coords = island_data["boundaries_coordinates"]
KeyError: 'boundaries_coordinates'

The above exception was the direct cause of the following exception:

Traceback (most recent call last):
  File "E:\Onepiecebot\Discordop\lib\site-packages\discord\ext\commands\bot.py", line 1350, in invoke
    await ctx.command.invoke(ctx)
  File "E:\Onepiecebot\Discordop\lib\site-packages\discord\ext\commands\core.py", line 1029, in invoke
    await injected(*ctx.args, **ctx.kwargs)  # type: ignore
  File "E:\Onepiecebot\Discordop\lib\site-packages\discord\ext\commands\core.py", line 244, in wrapped
    raise CommandInvokeError(exc) from exc
discord.ext.commands.errors.CommandInvokeError: Command raised an exception: KeyError: 'boundaries_coordinates'
ERROR      - 2023-09-18 04:40:05,917 - client          : Attempting a reconnect in 1.94s
Traceback (most recent call last):
  File "E:\Onepiecebot\Discordop\lib\site-packages\aiohttp\connector.py", line 1152, in _create_direct_connection
    hosts = await asyncio.shield(host_resolved)
  File "E:\Onepiecebot\Discordop\lib\site-packages\aiohttp\connector.py", line 874, in _resolve_host
    addrs = await self._resolver.resolve(host, port, family=self._family)
  File "E:\Onepiecebot\Discordop\lib\site-packages\aiohttp\resolver.py", line 33, in resolve
    infos = await self._loop.getaddrinfo(
  File "C:\Users\Lenovo\AppData\Local\Programs\Python\Python310\lib\asyncio\base_events.py", line 863, in getaddrinfo
    return await self.run_in_executor(
  File "C:\Users\Lenovo\AppData\Local\Programs\Python\Python310\lib\concurrent\futures\thread.py", line 58, in run
    result = self.fn(*self.args, **self.kwargs)
  File "C:\Users\Lenovo\AppData\Local\Programs\Python\Python310\lib\socket.py", line 955, in getaddrinfo
    for res in _socket.getaddrinfo(host, port, family, type, proto, flags):
socket.gaierror: [Errno 11001] getaddrinfo failed

The above exception was the direct cause of the following exception:

Traceback (most recent call last):
  File "E:\Onepiecebot\Discordop\lib\site-packages\discord\client.py", line 656, in connect
    self.ws = await asyncio.wait_for(coro, timeout=60.0)
  File "C:\Users\Lenovo\AppData\Local\Programs\Python\Python310\lib\asyncio\tasks.py", line 445, in wait_for
    return fut.result()
  File "E:\Onepiecebot\Discordop\lib\site-packages\discord\gateway.py", line 372, in from_client
    socket = await client.http.ws_connect(str(url))
  File "E:\Onepiecebot\Discordop\lib\site-packages\discord\http.py", line 537, in ws_connect
    return await self.__session.ws_connect(url, **kwargs)
  File "E:\Onepiecebot\Discordop\lib\site-packages\aiohttp\client.py", line 779, in _ws_connect
    resp = await self.request(
  File "E:\Onepiecebot\Discordop\lib\site-packages\aiohttp\client.py", line 536, in _request
    conn = await self._connector.connect(
  File "E:\Onepiecebot\Discordop\lib\site-packages\aiohttp\connector.py", line 540, in connect
    proto = await self._create_connection(req, traces, timeout)
  File "E:\Onepiecebot\Discordop\lib\site-packages\aiohttp\connector.py", line 901, in _create_connection
    _, proto = await self._create_direct_connection(req, traces, timeout)
  File "E:\Onepiecebot\Discordop\lib\site-packages\aiohttp\connector.py", line 1166, in _create_direct_connection
    raise ClientConnectorError(req.connection_key, exc) from exc
aiohttp.client_exceptions.ClientConnectorError: Cannot connect to host gateway-us-east1-c.discord.gg:443 ssl:default [getaddrinfo failed]
ERROR      - 2023-09-18 04:40:12,650 - client          : Attempting a reconnect in 0.63s
Traceback (most recent call last):
  File "E:\Onepiecebot\Discordop\lib\site-packages\aiohttp\connector.py", line 1152, in _create_direct_connection
    hosts = await asyncio.shield(host_resolved)
  File "E:\Onepiecebot\Discordop\lib\site-packages\aiohttp\connector.py", line 874, in _resolve_host
    addrs = await self._resolver.resolve(host, port, family=self._family)
  File "E:\Onepiecebot\Discordop\lib\site-packages\aiohttp\resolver.py", line 33, in resolve
    infos = await self._loop.getaddrinfo(
  File "C:\Users\Lenovo\AppData\Local\Programs\Python\Python310\lib\asyncio\base_events.py", line 863, in getaddrinfo
    return await self.run_in_executor(
  File "C:\Users\Lenovo\AppData\Local\Programs\Python\Python310\lib\concurrent\futures\thread.py", line 58, in run
    result = self.fn(*self.args, **self.kwargs)
  File "C:\Users\Lenovo\AppData\Local\Programs\Python\Python310\lib\socket.py", line 955, in getaddrinfo
    for res in _socket.getaddrinfo(host, port, family, type, proto, flags):
socket.gaierror: [Errno 11001] getaddrinfo failed

The above exception was the direct cause of the following exception:

Traceback (most recent call last):
  File "E:\Onepiecebot\Discordop\lib\site-packages\discord\client.py", line 656, in connect
    self.ws = await asyncio.wait_for(coro, timeout=60.0)
  File "C:\Users\Lenovo\AppData\Local\Programs\Python\Python310\lib\asyncio\tasks.py", line 445, in wait_for
    return fut.result()
  File "E:\Onepiecebot\Discordop\lib\site-packages\discord\gateway.py", line 372, in from_client
    socket = await client.http.ws_connect(str(url))
  File "E:\Onepiecebot\Discordop\lib\site-packages\discord\http.py", line 537, in ws_connect
    return await self.__session.ws_connect(url, **kwargs)
  File "E:\Onepiecebot\Discordop\lib\site-packages\aiohttp\client.py", line 779, in _ws_connect
    resp = await self.request(
  File "E:\Onepiecebot\Discordop\lib\site-packages\aiohttp\client.py", line 536, in _request
    conn = await self._connector.connect(
  File "E:\Onepiecebot\Discordop\lib\site-packages\aiohttp\connector.py", line 540, in connect
    proto = await self._create_connection(req, traces, timeout)
  File "E:\Onepiecebot\Discordop\lib\site-packages\aiohttp\connector.py", line 901, in _create_connection
    _, proto = await self._create_direct_connection(req, traces, timeout)
  File "E:\Onepiecebot\Discordop\lib\site-packages\aiohttp\connector.py", line 1166, in _create_direct_connection
    raise ClientConnectorError(req.connection_key, exc) from exc
aiohttp.client_exceptions.ClientConnectorError: Cannot connect to host gateway-us-east1-c.discord.gg:443 ssl:default [getaddrinfo failed]
ERROR      - 2023-09-18 04:40:13,299 - client          : Attempting a reconnect in 2.35s
Traceback (most recent call last):
  File "E:\Onepiecebot\Discordop\lib\site-packages\aiohttp\connector.py", line 1152, in _create_direct_connection
    hosts = await asyncio.shield(host_resolved)
  File "E:\Onepiecebot\Discordop\lib\site-packages\aiohttp\connector.py", line 874, in _resolve_host
    addrs = await self._resolver.resolve(host, port, family=self._family)
  File "E:\Onepiecebot\Discordop\lib\site-packages\aiohttp\resolver.py", line 33, in resolve
    infos = await self._loop.getaddrinfo(
  File "C:\Users\Lenovo\AppData\Local\Programs\Python\Python310\lib\asyncio\base_events.py", line 863, in getaddrinfo
    return await self.run_in_executor(
  File "C:\Users\Lenovo\AppData\Local\Programs\Python\Python310\lib\concurrent\futures\thread.py", line 58, in run
    result = self.fn(*self.args, **self.kwargs)
  File "C:\Users\Lenovo\AppData\Local\Programs\Python\Python310\lib\socket.py", line 955, in getaddrinfo
    for res in _socket.getaddrinfo(host, port, family, type, proto, flags):
socket.gaierror: [Errno 11001] getaddrinfo failed

The above exception was the direct cause of the following exception:

Traceback (most recent call last):
  File "E:\Onepiecebot\Discordop\lib\site-packages\discord\client.py", line 656, in connect
    self.ws = await asyncio.wait_for(coro, timeout=60.0)
  File "C:\Users\Lenovo\AppData\Local\Programs\Python\Python310\lib\asyncio\tasks.py", line 445, in wait_for
    return fut.result()
  File "E:\Onepiecebot\Discordop\lib\site-packages\discord\gateway.py", line 372, in from_client
    socket = await client.http.ws_connect(str(url))
  File "E:\Onepiecebot\Discordop\lib\site-packages\discord\http.py", line 537, in ws_connect
    return await self.__session.ws_connect(url, **kwargs)
  File "E:\Onepiecebot\Discordop\lib\site-packages\aiohttp\client.py", line 779, in _ws_connect
    resp = await self.request(
  File "E:\Onepiecebot\Discordop\lib\site-packages\aiohttp\client.py", line 536, in _request
    conn = await self._connector.connect(
  File "E:\Onepiecebot\Discordop\lib\site-packages\aiohttp\connector.py", line 540, in connect
    proto = await self._create_connection(req, traces, timeout)
  File "E:\Onepiecebot\Discordop\lib\site-packages\aiohttp\connector.py", line 901, in _create_connection
    _, proto = await self._create_direct_connection(req, traces, timeout)
  File "E:\Onepiecebot\Discordop\lib\site-packages\aiohttp\connector.py", line 1166, in _create_direct_connection
    raise ClientConnectorError(req.connection_key, exc) from exc
aiohttp.client_exceptions.ClientConnectorError: Cannot connect to host gateway-us-east1-c.discord.gg:443 ssl:default [getaddrinfo failed]
ERROR      - 2023-09-18 09:06:17,259 - client          : Attempting a reconnect in 1.31s
Traceback (most recent call last):
  File "E:\Onepiecebot\Discordop\lib\site-packages\discord\client.py", line 656, in connect
    self.ws = await asyncio.wait_for(coro, timeout=60.0)
  File "C:\Users\Lenovo\AppData\Local\Programs\Python\Python310\lib\asyncio\tasks.py", line 456, in wait_for
    return fut.result()
  File "E:\Onepiecebot\Discordop\lib\site-packages\discord\gateway.py", line 372, in from_client
    socket = await client.http.ws_connect(str(url))
  File "E:\Onepiecebot\Discordop\lib\site-packages\discord\http.py", line 537, in ws_connect
    return await self.__session.ws_connect(url, **kwargs)
  File "E:\Onepiecebot\Discordop\lib\site-packages\aiohttp\client.py", line 779, in _ws_connect
    resp = await self.request(
  File "E:\Onepiecebot\Discordop\lib\site-packages\aiohttp\client.py", line 467, in _request
    with timer:
  File "E:\Onepiecebot\Discordop\lib\site-packages\aiohttp\helpers.py", line 721, in __exit__
    raise asyncio.TimeoutError from None
asyncio.exceptions.TimeoutError
ERROR      - 2023-09-18 09:06:45,636 - client          : Attempting a reconnect in 2.30s
Traceback (most recent call last):
  File "E:\Onepiecebot\Discordop\lib\site-packages\aiohttp\connector.py", line 1152, in _create_direct_connection
    hosts = await asyncio.shield(host_resolved)
  File "E:\Onepiecebot\Discordop\lib\site-packages\aiohttp\connector.py", line 874, in _resolve_host
    addrs = await self._resolver.resolve(host, port, family=self._family)
  File "E:\Onepiecebot\Discordop\lib\site-packages\aiohttp\resolver.py", line 33, in resolve
    infos = await self._loop.getaddrinfo(
  File "C:\Users\Lenovo\AppData\Local\Programs\Python\Python310\lib\asyncio\base_events.py", line 863, in getaddrinfo
    return await self.run_in_executor(
  File "C:\Users\Lenovo\AppData\Local\Programs\Python\Python310\lib\concurrent\futures\thread.py", line 58, in run
    result = self.fn(*self.args, **self.kwargs)
  File "C:\Users\Lenovo\AppData\Local\Programs\Python\Python310\lib\socket.py", line 955, in getaddrinfo
    for res in _socket.getaddrinfo(host, port, family, type, proto, flags):
socket.gaierror: [Errno 11001] getaddrinfo failed

The above exception was the direct cause of the following exception:

Traceback (most recent call last):
  File "E:\Onepiecebot\Discordop\lib\site-packages\discord\client.py", line 656, in connect
    self.ws = await asyncio.wait_for(coro, timeout=60.0)
  File "C:\Users\Lenovo\AppData\Local\Programs\Python\Python310\lib\asyncio\tasks.py", line 445, in wait_for
    return fut.result()
  File "E:\Onepiecebot\Discordop\lib\site-packages\discord\gateway.py", line 372, in from_client
    socket = await client.http.ws_connect(str(url))
  File "E:\Onepiecebot\Discordop\lib\site-packages\discord\http.py", line 537, in ws_connect
    return await self.__session.ws_connect(url, **kwargs)
  File "E:\Onepiecebot\Discordop\lib\site-packages\aiohttp\client.py", line 779, in _ws_connect
    resp = await self.request(
  File "E:\Onepiecebot\Discordop\lib\site-packages\aiohttp\client.py", line 536, in _request
    conn = await self._connector.connect(
  File "E:\Onepiecebot\Discordop\lib\site-packages\aiohttp\connector.py", line 540, in connect
    proto = await self._create_connection(req, traces, timeout)
  File "E:\Onepiecebot\Discordop\lib\site-packages\aiohttp\connector.py", line 901, in _create_connection
    _, proto = await self._create_direct_connection(req, traces, timeout)
  File "E:\Onepiecebot\Discordop\lib\site-packages\aiohttp\connector.py", line 1166, in _create_direct_connection
    raise ClientConnectorError(req.connection_key, exc) from exc
aiohttp.client_exceptions.ClientConnectorError: Cannot connect to host gateway-us-east1-c.discord.gg:443 ssl:default [getaddrinfo failed]
ERROR      - 2023-09-18 09:06:48,541 - client          : Attempting a reconnect in 7.99s
Traceback (most recent call last):
  File "E:\Onepiecebot\Discordop\lib\site-packages\aiohttp\connector.py", line 1152, in _create_direct_connection
    hosts = await asyncio.shield(host_resolved)
  File "E:\Onepiecebot\Discordop\lib\site-packages\aiohttp\connector.py", line 874, in _resolve_host
    addrs = await self._resolver.resolve(host, port, family=self._family)
  File "E:\Onepiecebot\Discordop\lib\site-packages\aiohttp\resolver.py", line 33, in resolve
    infos = await self._loop.getaddrinfo(
  File "C:\Users\Lenovo\AppData\Local\Programs\Python\Python310\lib\asyncio\base_events.py", line 863, in getaddrinfo
    return await self.run_in_executor(
  File "C:\Users\Lenovo\AppData\Local\Programs\Python\Python310\lib\concurrent\futures\thread.py", line 58, in run
    result = self.fn(*self.args, **self.kwargs)
  File "C:\Users\Lenovo\AppData\Local\Programs\Python\Python310\lib\socket.py", line 955, in getaddrinfo
    for res in _socket.getaddrinfo(host, port, family, type, proto, flags):
socket.gaierror: [Errno 11001] getaddrinfo failed

The above exception was the direct cause of the following exception:

Traceback (most recent call last):
  File "E:\Onepiecebot\Discordop\lib\site-packages\discord\client.py", line 656, in connect
    self.ws = await asyncio.wait_for(coro, timeout=60.0)
  File "C:\Users\Lenovo\AppData\Local\Programs\Python\Python310\lib\asyncio\tasks.py", line 445, in wait_for
    return fut.result()
  File "E:\Onepiecebot\Discordop\lib\site-packages\discord\gateway.py", line 372, in from_client
    socket = await client.http.ws_connect(str(url))
  File "E:\Onepiecebot\Discordop\lib\site-packages\discord\http.py", line 537, in ws_connect
    return await self.__session.ws_connect(url, **kwargs)
  File "E:\Onepiecebot\Discordop\lib\site-packages\aiohttp\client.py", line 779, in _ws_connect
    resp = await self.request(
  File "E:\Onepiecebot\Discordop\lib\site-packages\aiohttp\client.py", line 536, in _request
    conn = await self._connector.connect(
  File "E:\Onepiecebot\Discordop\lib\site-packages\aiohttp\connector.py", line 540, in connect
    proto = await self._create_connection(req, traces, timeout)
  File "E:\Onepiecebot\Discordop\lib\site-packages\aiohttp\connector.py", line 901, in _create_connection
    _, proto = await self._create_direct_connection(req, traces, timeout)
  File "E:\Onepiecebot\Discordop\lib\site-packages\aiohttp\connector.py", line 1166, in _create_direct_connection
    raise ClientConnectorError(req.connection_key, exc) from exc
aiohttp.client_exceptions.ClientConnectorError: Cannot connect to host gateway-us-east1-c.discord.gg:443 ssl:default [getaddrinfo failed]
ERROR      - 2023-09-18 09:06:56,796 - client          : Attempting a reconnect in 5.66s
Traceback (most recent call last):
  File "E:\Onepiecebot\Discordop\lib\site-packages\aiohttp\connector.py", line 1152, in _create_direct_connection
    hosts = await asyncio.shield(host_resolved)
  File "E:\Onepiecebot\Discordop\lib\site-packages\aiohttp\connector.py", line 874, in _resolve_host
    addrs = await self._resolver.resolve(host, port, family=self._family)
  File "E:\Onepiecebot\Discordop\lib\site-packages\aiohttp\resolver.py", line 33, in resolve
    infos = await self._loop.getaddrinfo(
  File "C:\Users\Lenovo\AppData\Local\Programs\Python\Python310\lib\asyncio\base_events.py", line 863, in getaddrinfo
    return await self.run_in_executor(
  File "C:\Users\Lenovo\AppData\Local\Programs\Python\Python310\lib\concurrent\futures\thread.py", line 58, in run
    result = self.fn(*self.args, **self.kwargs)
  File "C:\Users\Lenovo\AppData\Local\Programs\Python\Python310\lib\socket.py", line 955, in getaddrinfo
    for res in _socket.getaddrinfo(host, port, family, type, proto, flags):
socket.gaierror: [Errno 11001] getaddrinfo failed

The above exception was the direct cause of the following exception:

Traceback (most recent call last):
  File "E:\Onepiecebot\Discordop\lib\site-packages\discord\client.py", line 656, in connect
    self.ws = await asyncio.wait_for(coro, timeout=60.0)
  File "C:\Users\Lenovo\AppData\Local\Programs\Python\Python310\lib\asyncio\tasks.py", line 445, in wait_for
    return fut.result()
  File "E:\Onepiecebot\Discordop\lib\site-packages\discord\gateway.py", line 372, in from_client
    socket = await client.http.ws_connect(str(url))
  File "E:\Onepiecebot\Discordop\lib\site-packages\discord\http.py", line 537, in ws_connect
    return await self.__session.ws_connect(url, **kwargs)
  File "E:\Onepiecebot\Discordop\lib\site-packages\aiohttp\client.py", line 779, in _ws_connect
    resp = await self.request(
  File "E:\Onepiecebot\Discordop\lib\site-packages\aiohttp\client.py", line 536, in _request
    conn = await self._connector.connect(
  File "E:\Onepiecebot\Discordop\lib\site-packages\aiohttp\connector.py", line 540, in connect
    proto = await self._create_connection(req, traces, timeout)
  File "E:\Onepiecebot\Discordop\lib\site-packages\aiohttp\connector.py", line 901, in _create_connection
    _, proto = await self._create_direct_connection(req, traces, timeout)
  File "E:\Onepiecebot\Discordop\lib\site-packages\aiohttp\connector.py", line 1166, in _create_direct_connection
    raise ClientConnectorError(req.connection_key, exc) from exc
aiohttp.client_exceptions.ClientConnectorError: Cannot connect to host gateway-us-east1-c.discord.gg:443 ssl:default [getaddrinfo failed]
ERROR      - 2023-09-18 09:07:02,470 - client          : Attempting a reconnect in 4.49s
Traceback (most recent call last):
  File "E:\Onepiecebot\Discordop\lib\site-packages\aiohttp\connector.py", line 1152, in _create_direct_connection
    hosts = await asyncio.shield(host_resolved)
  File "E:\Onepiecebot\Discordop\lib\site-packages\aiohttp\connector.py", line 874, in _resolve_host
    addrs = await self._resolver.resolve(host, port, family=self._family)
  File "E:\Onepiecebot\Discordop\lib\site-packages\aiohttp\resolver.py", line 33, in resolve
    infos = await self._loop.getaddrinfo(
  File "C:\Users\Lenovo\AppData\Local\Programs\Python\Python310\lib\asyncio\base_events.py", line 863, in getaddrinfo
    return await self.run_in_executor(
  File "C:\Users\Lenovo\AppData\Local\Programs\Python\Python310\lib\concurrent\futures\thread.py", line 58, in run
    result = self.fn(*self.args, **self.kwargs)
  File "C:\Users\Lenovo\AppData\Local\Programs\Python\Python310\lib\socket.py", line 955, in getaddrinfo
    for res in _socket.getaddrinfo(host, port, family, type, proto, flags):
socket.gaierror: [Errno 11001] getaddrinfo failed

The above exception was the direct cause of the following exception:

Traceback (most recent call last):
  File "E:\Onepiecebot\Discordop\lib\site-packages\discord\client.py", line 656, in connect
    self.ws = await asyncio.wait_for(coro, timeout=60.0)
  File "C:\Users\Lenovo\AppData\Local\Programs\Python\Python310\lib\asyncio\tasks.py", line 445, in wait_for
    return fut.result()
  File "E:\Onepiecebot\Discordop\lib\site-packages\discord\gateway.py", line 372, in from_client
    socket = await client.http.ws_connect(str(url))
  File "E:\Onepiecebot\Discordop\lib\site-packages\discord\http.py", line 537, in ws_connect
    return await self.__session.ws_connect(url, **kwargs)
  File "E:\Onepiecebot\Discordop\lib\site-packages\aiohttp\client.py", line 779, in _ws_connect
    resp = await self.request(
  File "E:\Onepiecebot\Discordop\lib\site-packages\aiohttp\client.py", line 536, in _request
    conn = await self._connector.connect(
  File "E:\Onepiecebot\Discordop\lib\site-packages\aiohttp\connector.py", line 540, in connect
    proto = await self._create_connection(req, traces, timeout)
  File "E:\Onepiecebot\Discordop\lib\site-packages\aiohttp\connector.py", line 901, in _create_connection
    _, proto = await self._create_direct_connection(req, traces, timeout)
  File "E:\Onepiecebot\Discordop\lib\site-packages\aiohttp\connector.py", line 1166, in _create_direct_connection
    raise ClientConnectorError(req.connection_key, exc) from exc
aiohttp.client_exceptions.ClientConnectorError: Cannot connect to host gateway-us-east1-c.discord.gg:443 ssl:default [getaddrinfo failed]
ERROR      - 2023-09-18 09:07:07,161 - client          : Attempting a reconnect in 52.21s
Traceback (most recent call last):
  File "E:\Onepiecebot\Discordop\lib\site-packages\aiohttp\connector.py", line 1152, in _create_direct_connection
    hosts = await asyncio.shield(host_resolved)
  File "E:\Onepiecebot\Discordop\lib\site-packages\aiohttp\connector.py", line 874, in _resolve_host
    addrs = await self._resolver.resolve(host, port, family=self._family)
  File "E:\Onepiecebot\Discordop\lib\site-packages\aiohttp\resolver.py", line 33, in resolve
    infos = await self._loop.getaddrinfo(
  File "C:\Users\Lenovo\AppData\Local\Programs\Python\Python310\lib\asyncio\base_events.py", line 863, in getaddrinfo
    return await self.run_in_executor(
  File "C:\Users\Lenovo\AppData\Local\Programs\Python\Python310\lib\concurrent\futures\thread.py", line 58, in run
    result = self.fn(*self.args, **self.kwargs)
  File "C:\Users\Lenovo\AppData\Local\Programs\Python\Python310\lib\socket.py", line 955, in getaddrinfo
    for res in _socket.getaddrinfo(host, port, family, type, proto, flags):
socket.gaierror: [Errno 11001] getaddrinfo failed

The above exception was the direct cause of the following exception:

Traceback (most recent call last):
  File "E:\Onepiecebot\Discordop\lib\site-packages\discord\client.py", line 656, in connect
    self.ws = await asyncio.wait_for(coro, timeout=60.0)
  File "C:\Users\Lenovo\AppData\Local\Programs\Python\Python310\lib\asyncio\tasks.py", line 445, in wait_for
    return fut.result()
  File "E:\Onepiecebot\Discordop\lib\site-packages\discord\gateway.py", line 372, in from_client
    socket = await client.http.ws_connect(str(url))
  File "E:\Onepiecebot\Discordop\lib\site-packages\discord\http.py", line 537, in ws_connect
    return await self.__session.ws_connect(url, **kwargs)
  File "E:\Onepiecebot\Discordop\lib\site-packages\aiohttp\client.py", line 779, in _ws_connect
    resp = await self.request(
  File "E:\Onepiecebot\Discordop\lib\site-packages\aiohttp\client.py", line 536, in _request
    conn = await self._connector.connect(
  File "E:\Onepiecebot\Discordop\lib\site-packages\aiohttp\connector.py", line 540, in connect
    proto = await self._create_connection(req, traces, timeout)
  File "E:\Onepiecebot\Discordop\lib\site-packages\aiohttp\connector.py", line 901, in _create_connection
    _, proto = await self._create_direct_connection(req, traces, timeout)
  File "E:\Onepiecebot\Discordop\lib\site-packages\aiohttp\connector.py", line 1166, in _create_direct_connection
    raise ClientConnectorError(req.connection_key, exc) from exc
aiohttp.client_exceptions.ClientConnectorError: Cannot connect to host gateway-us-east1-c.discord.gg:443 ssl:default [getaddrinfo failed]
ERROR      - 2023-09-18 09:07:59,375 - client          : Attempting a reconnect in 74.32s
Traceback (most recent call last):
  File "E:\Onepiecebot\Discordop\lib\site-packages\aiohttp\connector.py", line 1152, in _create_direct_connection
    hosts = await asyncio.shield(host_resolved)
  File "E:\Onepiecebot\Discordop\lib\site-packages\aiohttp\connector.py", line 874, in _resolve_host
    addrs = await self._resolver.resolve(host, port, family=self._family)
  File "E:\Onepiecebot\Discordop\lib\site-packages\aiohttp\resolver.py", line 33, in resolve
    infos = await self._loop.getaddrinfo(
  File "C:\Users\Lenovo\AppData\Local\Programs\Python\Python310\lib\asyncio\base_events.py", line 863, in getaddrinfo
    return await self.run_in_executor(
  File "C:\Users\Lenovo\AppData\Local\Programs\Python\Python310\lib\concurrent\futures\thread.py", line 58, in run
    result = self.fn(*self.args, **self.kwargs)
  File "C:\Users\Lenovo\AppData\Local\Programs\Python\Python310\lib\socket.py", line 955, in getaddrinfo
    for res in _socket.getaddrinfo(host, port, family, type, proto, flags):
socket.gaierror: [Errno 11001] getaddrinfo failed

The above exception was the direct cause of the following exception:

Traceback (most recent call last):
  File "E:\Onepiecebot\Discordop\lib\site-packages\discord\client.py", line 656, in connect
    self.ws = await asyncio.wait_for(coro, timeout=60.0)
  File "C:\Users\Lenovo\AppData\Local\Programs\Python\Python310\lib\asyncio\tasks.py", line 445, in wait_for
    return fut.result()
  File "E:\Onepiecebot\Discordop\lib\site-packages\discord\gateway.py", line 372, in from_client
    socket = await client.http.ws_connect(str(url))
  File "E:\Onepiecebot\Discordop\lib\site-packages\discord\http.py", line 537, in ws_connect
    return await self.__session.ws_connect(url, **kwargs)
  File "E:\Onepiecebot\Discordop\lib\site-packages\aiohttp\client.py", line 779, in _ws_connect
    resp = await self.request(
  File "E:\Onepiecebot\Discordop\lib\site-packages\aiohttp\client.py", line 536, in _request
    conn = await self._connector.connect(
  File "E:\Onepiecebot\Discordop\lib\site-packages\aiohttp\connector.py", line 540, in connect
    proto = await self._create_connection(req, traces, timeout)
  File "E:\Onepiecebot\Discordop\lib\site-packages\aiohttp\connector.py", line 901, in _create_connection
    _, proto = await self._create_direct_connection(req, traces, timeout)
  File "E:\Onepiecebot\Discordop\lib\site-packages\aiohttp\connector.py", line 1166, in _create_direct_connection
    raise ClientConnectorError(req.connection_key, exc) from exc
aiohttp.client_exceptions.ClientConnectorError: Cannot connect to host gateway-us-east1-c.discord.gg:443 ssl:default [getaddrinfo failed]
INFO       - 2023-09-18 09:09:14,921 - gateway         : Shard ID None session has been invalidated.
INFO       - 2023-09-18 09:09:21,656 - gateway         : Shard ID None has connected to Gateway (Session ID: 089eab69e897feffa1d315098c66d3e9).
ERROR      - 2023-09-18 09:09:23,795 - client          : Ignoring exception in on_ready
Traceback (most recent call last):
  File "E:\Onepiecebot\Discordop\lib\site-packages\discord\client.py", line 441, in _run_event
    await coro(*args, **kwargs)
  File "e:\Onepiecebot\main.py", line 26, in on_ready
    await load_cogs()
  File "e:\Onepiecebot\main.py", line 20, in load_cogs
    await bot.load_extension(f"Cmds.{cog_file.stem}")
  File "E:\Onepiecebot\Discordop\lib\site-packages\discord\ext\commands\bot.py", line 1007, in load_extension
    raise errors.ExtensionAlreadyLoaded(name)
discord.ext.commands.errors.ExtensionAlreadyLoaded: Extension 'Cmds.island' is already loaded.
ERROR      - 2023-09-18 09:22:14,338 - client          : Attempting a reconnect in 33.11s
Traceback (most recent call last):
  File "E:\Onepiecebot\Discordop\lib\site-packages\aiohttp\connector.py", line 1152, in _create_direct_connection
    hosts = await asyncio.shield(host_resolved)
  File "E:\Onepiecebot\Discordop\lib\site-packages\aiohttp\connector.py", line 874, in _resolve_host
    addrs = await self._resolver.resolve(host, port, family=self._family)
  File "E:\Onepiecebot\Discordop\lib\site-packages\aiohttp\resolver.py", line 33, in resolve
    infos = await self._loop.getaddrinfo(
  File "C:\Users\Lenovo\AppData\Local\Programs\Python\Python310\lib\asyncio\base_events.py", line 863, in getaddrinfo
    return await self.run_in_executor(
  File "C:\Users\Lenovo\AppData\Local\Programs\Python\Python310\lib\concurrent\futures\thread.py", line 58, in run
    result = self.fn(*self.args, **self.kwargs)
  File "C:\Users\Lenovo\AppData\Local\Programs\Python\Python310\lib\socket.py", line 955, in getaddrinfo
    for res in _socket.getaddrinfo(host, port, family, type, proto, flags):
socket.gaierror: [Errno 11001] getaddrinfo failed

The above exception was the direct cause of the following exception:

Traceback (most recent call last):
  File "E:\Onepiecebot\Discordop\lib\site-packages\discord\client.py", line 656, in connect
    self.ws = await asyncio.wait_for(coro, timeout=60.0)
  File "C:\Users\Lenovo\AppData\Local\Programs\Python\Python310\lib\asyncio\tasks.py", line 445, in wait_for
    return fut.result()
  File "E:\Onepiecebot\Discordop\lib\site-packages\discord\gateway.py", line 372, in from_client
    socket = await client.http.ws_connect(str(url))
  File "E:\Onepiecebot\Discordop\lib\site-packages\discord\http.py", line 537, in ws_connect
    return await self.__session.ws_connect(url, **kwargs)
  File "E:\Onepiecebot\Discordop\lib\site-packages\aiohttp\client.py", line 779, in _ws_connect
    resp = await self.request(
  File "E:\Onepiecebot\Discordop\lib\site-packages\aiohttp\client.py", line 536, in _request
    conn = await self._connector.connect(
  File "E:\Onepiecebot\Discordop\lib\site-packages\aiohttp\connector.py", line 540, in connect
    proto = await self._create_connection(req, traces, timeout)
  File "E:\Onepiecebot\Discordop\lib\site-packages\aiohttp\connector.py", line 901, in _create_connection
    _, proto = await self._create_direct_connection(req, traces, timeout)
  File "E:\Onepiecebot\Discordop\lib\site-packages\aiohttp\connector.py", line 1166, in _create_direct_connection
    raise ClientConnectorError(req.connection_key, exc) from exc
aiohttp.client_exceptions.ClientConnectorError: Cannot connect to host gateway-us-east1-c.discord.gg:443 ssl:default [getaddrinfo failed]
INFO       - 2023-09-18 09:22:48,830 - gateway         : Shard ID None has successfully RESUMED session 089eab69e897feffa1d315098c66d3e9.
